Traceback (most recent call last):
  File "/home/xie/anaconda3/envs/PyDimension/lib/python3.11/site-packages/jupyter_cache/executors/utils.py", line 51, in single_nb_execution
    executenb(
  File "/home/xie/anaconda3/envs/PyDimension/lib/python3.11/site-packages/nbclient/client.py", line 1204, in execute
    return NotebookClient(nb=nb, resources=resources, km=km, **kwargs).execute()
           ^^^^^^^^^^^^^^^^^^^^^^^^^^^^^^^^^^^^^^^^^^^^^^^^^^^^^^^^^^^^^^^^^^^^^
  File "/home/xie/anaconda3/envs/PyDimension/lib/python3.11/site-packages/nbclient/util.py", line 84, in wrapped
    return just_run(coro(*args, **kwargs))
           ^^^^^^^^^^^^^^^^^^^^^^^^^^^^^^^
  File "/home/xie/anaconda3/envs/PyDimension/lib/python3.11/site-packages/nbclient/util.py", line 62, in just_run
    return loop.run_until_complete(coro)
           ^^^^^^^^^^^^^^^^^^^^^^^^^^^^^
  File "/home/xie/anaconda3/envs/PyDimension/lib/python3.11/asyncio/base_events.py", line 650, in run_until_complete
    return future.result()
           ^^^^^^^^^^^^^^^
  File "/home/xie/anaconda3/envs/PyDimension/lib/python3.11/contextlib.py", line 222, in __aexit__
    await self.gen.athrow(typ, value, traceback)
  File "/home/xie/anaconda3/envs/PyDimension/lib/python3.11/site-packages/nbclient/client.py", line 608, in async_setup_kernel
    yield
  File "/home/xie/anaconda3/envs/PyDimension/lib/python3.11/site-packages/nbclient/client.py", line 663, in async_execute
    await self.async_execute_cell(
  File "/home/xie/anaconda3/envs/PyDimension/lib/python3.11/site-packages/nbclient/client.py", line 965, in async_execute_cell
    await self._check_raise_for_error(cell, cell_index, exec_reply)
  File "/home/xie/anaconda3/envs/PyDimension/lib/python3.11/site-packages/nbclient/client.py", line 862, in _check_raise_for_error
    raise CellExecutionError.from_cell_and_msg(cell, exec_reply_content)
nbclient.exceptions.CellExecutionError: An error occurred while executing the following cell:
------------------
import os
import sys
sys.path.append('/home/xie/projects/PyDimension')

import pandas as pd
import matplotlib.pyplot as plt
import numpy as np
from sklearn.linear_model import LinearRegression
from sklearn.metrics import r2_score

from utils.PolyDiff import PolyDiffPoint
from utils.SeqReg import SeqReg

%matplotlib inline
plt.rcParams["font.family"] = "Arial"
np.set_printoptions(suppress=True)
------------------

[0;31m---------------------------------------------------------------------------[0m
[0;31mModuleNotFoundError[0m                       Traceback (most recent call last)
Cell [0;32mIn[1], line 11[0m
[1;32m      8[0m [38;5;28;01mfrom[39;00m [38;5;21;01msklearn[39;00m[38;5;21;01m.[39;00m[38;5;21;01mlinear_model[39;00m [38;5;28;01mimport[39;00m LinearRegression
[1;32m      9[0m [38;5;28;01mfrom[39;00m [38;5;21;01msklearn[39;00m[38;5;21;01m.[39;00m[38;5;21;01mmetrics[39;00m [38;5;28;01mimport[39;00m r2_score
[0;32m---> 11[0m [38;5;28;01mfrom[39;00m [38;5;21;01mutils[39;00m[38;5;21;01m.[39;00m[38;5;21;01mPolyDiff[39;00m [38;5;28;01mimport[39;00m PolyDiffPoint
[1;32m     12[0m [38;5;28;01mfrom[39;00m [38;5;21;01mutils[39;00m[38;5;21;01m.[39;00m[38;5;21;01mSeqReg[39;00m [38;5;28;01mimport[39;00m SeqReg
[1;32m     14[0m get_ipython()[38;5;241m.[39mrun_line_magic([38;5;124m'[39m[38;5;124mmatplotlib[39m[38;5;124m'[39m, [38;5;124m'[39m[38;5;124minline[39m[38;5;124m'[39m)

[0;31mModuleNotFoundError[0m: No module named 'utils.PolyDiff'
ModuleNotFoundError: No module named 'utils.PolyDiff'

